<?xml version="1.0" ?>
<robot name="qbdelta" xmlns:xacro="http://www.ros.org/wiki/xacro">
  <material name="qbmove/flange">
    <color rgba="0.0 0.5 0.8 1.0"/>
  </material>
  <material name="qbmove/cube">
    <color rgba="0.35 0.35 0.35 1.0"/>
  </material>
  <material name="qbmove/shaft">
    <color rgba="0.8 0.8 0.8 1.0"/>
  </material>
  <material name="qbmove/default">
    <color rgba="0.35 0.35 0.35 1.0"/>
  </material>
  <link name="root_link"/>
  <joint name="delta_base_frame_joint" type="fixed">
    <origin rpy="0 3.14 3.14" xyz="0 0 0.45"/>
    <parent link="root_link"/>
    <child link="delta_base_frame_link"/>
  </joint>
  <link name="delta_base_frame_link"/>
  <joint name="delta_upper_plate_fixed_joint" type="fixed">
    <origin rpy="-1.57 3.14 -1.57" xyz="0 0 -0.048"/>
    <parent link="delta_base_frame_link"/>
    <child link="delta_upper_plate_link"/>
  </joint>
  <link name="delta_upper_plate_link">
    <inertial>
      <mass value="0.0"/>
      <origin xyz="0.0 0.0 0.0"/>
      <inertia ixx="0.0" ixy="0.0" ixz="0.0" iyy="0.0" iyz="0.0" izz="0.0"/>
    </inertial>
    <visual>
      <origin rpy="0 0 0" xyz="0 0 0"/>
      <geometry>
        <mesh filename="delta-meshes/qb_delta_upper_plate.stl" scale="0.001 0.001 0.001"/>
      </geometry>
      <material name="qbmove/flange"/>
    </visual>
  </link>
  <joint name="delta_qbmove_1_flat_flange_fixed_joint" type="fixed">
    <origin rpy="-1.57 3.14 0" xyz="0 0.015 0.1"/>
    <parent link="delta_upper_plate_link"/>
    <child link="delta_qbmove_1_flat_flange_link"/>
  </joint>
  <link name="delta_qbmove_1_flat_flange_link">
    <inertial>
      <mass value="0.0"/>
      <origin xyz="0.0 0.0 0.0"/>
      <inertia ixx="0.0" ixy="0.0" ixz="0.0" iyy="0.0" iyz="0.0" izz="0.0"/>
    </inertial>
    <visual>
      <origin rpy="0 0 0" xyz="0 0 0"/>
      <geometry>
        <mesh filename="delta-meshes/qb_flat_flange.stl" scale="0.001 0.001 0.001"/>
      </geometry>
      <material name="qbmove/flange"/>
    </visual>
  </link>
  <joint name="delta_qbmove_1_cube_fixed_joint" type="fixed">
    <origin rpy="1.57 0 -1.57" xyz="0.033 0 0.033"/>
    <parent link="delta_qbmove_1_flat_flange_link"/>
    <child link="delta_qbmove_1_cube_link"/>
  </joint>
  <link name="delta_qbmove_1_cube_link">
    <inertial>
      <mass value="0.6"/>
      <origin xyz="0.0 0.0 0.05"/>
      <inertia ixx="0.001" ixy="0.0" ixz="0.0" iyy="0.001" iyz="0.0" izz="0.001"/>
    </inertial>
    <visual>
      <origin rpy="0 0 0" xyz="0 0 0"/>
      <geometry>
        <mesh filename="delta-meshes/qbmove_frame.stl" scale="0.001 0.001 0.001"/>
      </geometry>
      <material name="qbmove/cube"/>
    </visual>
  </link>
  <joint name="delta_qbmove_1_motor_1_joint" type="revolute">
    <origin rpy="0 0 0" xyz="0.02 0.02 0.02"/>
    <parent link="delta_qbmove_1_cube_link"/>
    <child link="delta_qbmove_1_motor_1_link"/>
    <axis xyz="0 1 0"/>
    <dynamics damping="0.0" friction="0.0"/>
    <limit effort="100" lower="-2.876" upper="2.876" velocity="100"/>
  </joint>
  <link name="delta_qbmove_1_motor_1_link">
    <inertial>
      <mass value="0.05"/>
      <origin xyz="0.0 0.0 0.025"/>
      <inertia ixx="1.2e-05" ixy="0.0" ixz="0.0" iyy="1.2e-05" iyz="0.0" izz="3e-06"/>
    </inertial>
  </link>
  <joint name="delta_qbmove_1_motor_2_joint" type="revolute">
    <origin rpy="0 0 0" xyz="-0.02 -0.02 0.02"/>
    <parent link="delta_qbmove_1_cube_link"/>
    <child link="delta_qbmove_1_motor_2_link"/>
    <axis xyz="0 1 0"/>
    <dynamics damping="0.0" friction="0.0"/>
    <limit effort="100" lower="-2.876" upper="2.876" velocity="100"/>
  </joint>
  <link name="delta_qbmove_1_motor_2_link">
    <inertial>
      <mass value="0.05"/>
      <origin xyz="0.0 0.0 0.025"/>
      <inertia ixx="1.2e-05" ixy="0.0" ixz="0.0" iyy="1.2e-05" iyz="0.0" izz="3e-06"/>
    </inertial>
  </link>
  <joint name="delta_qbmove_1_shaft_joint" type="revolute">
    <origin rpy="1.57 0 0" xyz="0 0 0.056"/>
    <parent link="delta_qbmove_1_cube_link"/>
    <child link="delta_qbmove_1_shaft_link"/>
    <axis xyz="0 1 0"/>
    <dynamics damping="0.0" friction="0.0"/>
    <limit effort="100" lower="-2.876" upper="2.876" velocity="100"/>
  </joint>
  <link name="delta_qbmove_1_shaft_link">
    <inertial>
      <mass value="0.05"/>
      <origin xyz="0.0 0.0 0.005"/>
      <inertia ixx="1.2e-05" ixy="0.0" ixz="0.0" iyy="1.2e-05" iyz="0.0" izz="2.3e-05"/>
    </inertial>
    <visual>
      <origin rpy="0 0 0" xyz="0 0 0"/>
      <geometry>
        <mesh filename="delta-meshes/qbmove_pulley.stl" scale="0.001 0.001 0.001"/>
      </geometry>
      <material name="qbmove/shaft"/>
    </visual>
  </link>
  <joint name="delta_qbmove_1_stiffness_preset_virtual_joint" type="revolute">
    <origin rpy="0 0 0" xyz="0 0 0"/>
    <parent link="delta_qbmove_1_cube_link"/>
    <child link="delta_qbmove_1_stiffness_preset_virtual_link"/>
    <axis xyz="0 0 1"/>
    <dynamics damping="0.0" friction="0.0"/>
    <limit effort="100" lower="0.0" upper="1.0" velocity="100"/>
  </joint>
  <link name="delta_qbmove_1_stiffness_preset_virtual_link"/>
  <joint name="delta_qbmove_1_c_flange_axis_fixed_joint" type="fixed">
    <origin rpy="2.355 0 1.57" xyz="-0.0375 -0.024 -0.0375"/>
    <parent link="delta_qbmove_1_shaft_link"/>
    <child link="delta_qbmove_1_c_flange_axis_link"/>
  </joint>
  <link name="delta_qbmove_1_c_flange_axis_link">
    <inertial>
      <mass value="0.0"/>
      <origin xyz="0.0 0.0 0.0"/>
      <inertia ixx="0.0" ixy="0.0" ixz="0.0" iyy="0.0" iyz="0.0" izz="0.0"/>
    </inertial>
    <visual>
      <origin rpy="0 0 0" xyz="0 0 0"/>
      <geometry>
        <mesh filename="delta-meshes/qb_delta_c_flange.stl" scale="0.001 0.001 0.001"/>
      </geometry>
      <material name="qbmove/flange"/>
    </visual>
  </link>
  <joint name="delta_qbmove_1_upperarm_joint" type="fixed">
    <origin rpy="0 1.57 0" xyz="0 -0.035 0.02"/>
    <parent link="delta_qbmove_1_c_flange_axis_link"/>
    <child link="delta_qbmove_1_upperarm_link"/>
  </joint>
  <link name="delta_qbmove_1_upperarm_link"/>
  <joint name="delta_qbmove_3_flat_flange_fixed_joint" type="fixed">
    <origin rpy="-1.57 1.05 0" xyz="-0.0865 0.015 -0.05"/>
    <parent link="delta_upper_plate_link"/>
    <child link="delta_qbmove_3_flat_flange_link"/>
  </joint>
  <link name="delta_qbmove_3_flat_flange_link">
    <inertial>
      <mass value="0.0"/>
      <origin xyz="0.0 0.0 0.0"/>
      <inertia ixx="0.0" ixy="0.0" ixz="0.0" iyy="0.0" iyz="0.0" izz="0.0"/>
    </inertial>
    <visual>
      <origin rpy="0 0 0" xyz="0 0 0"/>
      <geometry>
        <mesh filename="delta-meshes/qb_flat_flange.stl" scale="0.001 0.001 0.001"/>
      </geometry>
      <material name="qbmove/flange"/>
    </visual>
  </link>
  <joint name="delta_qbmove_3_cube_fixed_joint" type="fixed">
    <origin rpy="1.57 0 -1.57" xyz="0.033 0 0.033"/>
    <parent link="delta_qbmove_3_flat_flange_link"/>
    <child link="delta_qbmove_3_cube_link"/>
  </joint>
  <link name="delta_qbmove_3_cube_link">
    <inertial>
      <mass value="0.6"/>
      <origin xyz="0.0 0.0 0.05"/>
      <inertia ixx="0.001" ixy="0.0" ixz="0.0" iyy="0.001" iyz="0.0" izz="0.001"/>
    </inertial>
    <visual>
      <origin rpy="0 0 0" xyz="0 0 0"/>
      <geometry>
        <mesh filename="delta-meshes/qbmove_frame.stl" scale="0.001 0.001 0.001"/>
      </geometry>
      <material name="qbmove/cube"/>
    </visual>
  </link>
  <joint name="delta_qbmove_3_motor_1_joint" type="revolute">
    <origin rpy="0 0 0" xyz="0.02 0.02 0.02"/>
    <parent link="delta_qbmove_3_cube_link"/>
    <child link="delta_qbmove_3_motor_1_link"/>
    <axis xyz="0 1 0"/>
    <dynamics damping="0.0" friction="0.0"/>
    <limit effort="100" lower="-2.876" upper="2.876" velocity="100"/>
  </joint>
  <link name="delta_qbmove_3_motor_1_link">
    <inertial>
      <mass value="0.05"/>
      <origin xyz="0.0 0.0 0.025"/>
      <inertia ixx="1.2e-05" ixy="0.0" ixz="0.0" iyy="1.2e-05" iyz="0.0" izz="3e-06"/>
    </inertial>
  </link>
  <joint name="delta_qbmove_3_motor_2_joint" type="revolute">
    <origin rpy="0 0 0" xyz="-0.02 -0.02 0.02"/>
    <parent link="delta_qbmove_3_cube_link"/>
    <child link="delta_qbmove_3_motor_2_link"/>
    <axis xyz="0 1 0"/>
    <dynamics damping="0.0" friction="0.0"/>
    <limit effort="100" lower="-2.876" upper="2.876" velocity="100"/>
  </joint>
  <link name="delta_qbmove_3_motor_2_link">
    <inertial>
      <mass value="0.05"/>
      <origin xyz="0.0 0.0 0.025"/>
      <inertia ixx="1.2e-05" ixy="0.0" ixz="0.0" iyy="1.2e-05" iyz="0.0" izz="3e-06"/>
    </inertial>
  </link>
  <joint name="delta_qbmove_3_shaft_joint" type="revolute">
    <origin rpy="1.57 0 0" xyz="0 0 0.056"/>
    <parent link="delta_qbmove_3_cube_link"/>
    <child link="delta_qbmove_3_shaft_link"/>
    <axis xyz="0 1 0"/>
    <dynamics damping="0.0" friction="0.0"/>
    <limit effort="100" lower="-2.876" upper="2.876" velocity="100"/>
  </joint>
  <link name="delta_qbmove_3_shaft_link">
    <inertial>
      <mass value="0.05"/>
      <origin xyz="0.0 0.0 0.005"/>
      <inertia ixx="1.2e-05" ixy="0.0" ixz="0.0" iyy="1.2e-05" iyz="0.0" izz="2.3e-05"/>
    </inertial>
    <visual>
      <origin rpy="0 0 0" xyz="0 0 0"/>
      <geometry>
        <mesh filename="delta-meshes/qbmove_pulley.stl" scale="0.001 0.001 0.001"/>
      </geometry>
      <material name="qbmove/shaft"/>
    </visual>
  </link>
  <joint name="delta_qbmove_3_stiffness_preset_virtual_joint" type="revolute">
    <origin rpy="0 0 0" xyz="0 0 0"/>
    <parent link="delta_qbmove_3_cube_link"/>
    <child link="delta_qbmove_3_stiffness_preset_virtual_link"/>
    <axis xyz="0 0 1"/>
    <dynamics damping="0.0" friction="0.0"/>
    <limit effort="100" lower="0.0" upper="1.0" velocity="100"/>
  </joint>
  <link name="delta_qbmove_3_stiffness_preset_virtual_link"/>
  <joint name="delta_qbmove_3_c_flange_axis_fixed_joint" type="fixed">
    <origin rpy="2.355 0 1.57" xyz="-0.0375 -0.024 -0.0375"/>
    <parent link="delta_qbmove_3_shaft_link"/>
    <child link="delta_qbmove_3_c_flange_axis_link"/>
  </joint>
  <link name="delta_qbmove_3_c_flange_axis_link">
    <inertial>
      <mass value="0.0"/>
      <origin xyz="0.0 0.0 0.0"/>
      <inertia ixx="0.0" ixy="0.0" ixz="0.0" iyy="0.0" iyz="0.0" izz="0.0"/>
    </inertial>
    <visual>
      <origin rpy="0 0 0" xyz="0 0 0"/>
      <geometry>
        <mesh filename="delta-meshes/qb_delta_c_flange.stl" scale="0.001 0.001 0.001"/>
      </geometry>
      <material name="qbmove/flange"/>
    </visual>
  </link>
  <joint name="delta_qbmove_3_upperarm_joint" type="fixed">
    <origin rpy="0 1.57 0" xyz="0 -0.035 0.02"/>
    <parent link="delta_qbmove_3_c_flange_axis_link"/>
    <child link="delta_qbmove_3_upperarm_link"/>
  </joint>
  <link name="delta_qbmove_3_upperarm_link"/>
  <joint name="delta_qbmove_2_flat_flange_fixed_joint" type="fixed">
    <origin rpy="-1.57 -1.05 0" xyz="0.0865 0.015 -0.05"/>
    <parent link="delta_upper_plate_link"/>
    <child link="delta_qbmove_2_flat_flange_link"/>
  </joint>
  <link name="delta_qbmove_2_flat_flange_link">
    <inertial>
      <mass value="0.0"/>
      <origin xyz="0.0 0.0 0.0"/>
      <inertia ixx="0.0" ixy="0.0" ixz="0.0" iyy="0.0" iyz="0.0" izz="0.0"/>
    </inertial>
    <visual>
      <origin rpy="0 0 0" xyz="0 0 0"/>
      <geometry>
        <mesh filename="delta-meshes/qb_flat_flange.stl" scale="0.001 0.001 0.001"/>
      </geometry>
      <material name="qbmove/flange"/>
    </visual>
  </link>
  <joint name="delta_qbmove_2_cube_fixed_joint" type="fixed">
    <origin rpy="1.57 0 -1.57" xyz="0.033 0 0.033"/>
    <parent link="delta_qbmove_2_flat_flange_link"/>
    <child link="delta_qbmove_2_cube_link"/>
  </joint>
  <link name="delta_qbmove_2_cube_link">
    <inertial>
      <mass value="0.6"/>
      <origin xyz="0.0 0.0 0.05"/>
      <inertia ixx="0.001" ixy="0.0" ixz="0.0" iyy="0.001" iyz="0.0" izz="0.001"/>
    </inertial>
    <visual>
      <origin rpy="0 0 0" xyz="0 0 0"/>
      <geometry>
        <mesh filename="delta-meshes/qbmove_frame.stl" scale="0.001 0.001 0.001"/>
      </geometry>
      <material name="qbmove/cube"/>
    </visual>
  </link>
  <joint name="delta_qbmove_2_motor_1_joint" type="revolute">
    <origin rpy="0 0 0" xyz="0.02 0.02 0.02"/>
    <parent link="delta_qbmove_2_cube_link"/>
    <child link="delta_qbmove_2_motor_1_link"/>
    <axis xyz="0 1 0"/>
    <dynamics damping="0.0" friction="0.0"/>
    <limit effort="100" lower="-2.876" upper="2.876" velocity="100"/>
  </joint>
  <link name="delta_qbmove_2_motor_1_link">
    <inertial>
      <mass value="0.05"/>
      <origin xyz="0.0 0.0 0.025"/>
      <inertia ixx="1.2e-05" ixy="0.0" ixz="0.0" iyy="1.2e-05" iyz="0.0" izz="3e-06"/>
    </inertial>
  </link>
  <joint name="delta_qbmove_2_motor_2_joint" type="revolute">
    <origin rpy="0 0 0" xyz="-0.02 -0.02 0.02"/>
    <parent link="delta_qbmove_2_cube_link"/>
    <child link="delta_qbmove_2_motor_2_link"/>
    <axis xyz="0 1 0"/>
    <dynamics damping="0.0" friction="0.0"/>
    <limit effort="100" lower="-2.876" upper="2.876" velocity="100"/>
  </joint>
  <link name="delta_qbmove_2_motor_2_link">
    <inertial>
      <mass value="0.05"/>
      <origin xyz="0.0 0.0 0.025"/>
      <inertia ixx="1.2e-05" ixy="0.0" ixz="0.0" iyy="1.2e-05" iyz="0.0" izz="3e-06"/>
    </inertial>
  </link>
  <joint name="delta_qbmove_2_shaft_joint" type="revolute">
    <origin rpy="1.57 0 0" xyz="0 0 0.056"/>
    <parent link="delta_qbmove_2_cube_link"/>
    <child link="delta_qbmove_2_shaft_link"/>
    <axis xyz="0 1 0"/>
    <dynamics damping="0.0" friction="0.0"/>
    <limit effort="100" lower="-2.876" upper="2.876" velocity="100"/>
  </joint>
  <link name="delta_qbmove_2_shaft_link">
    <inertial>
      <mass value="0.05"/>
      <origin xyz="0.0 0.0 0.005"/>
      <inertia ixx="1.2e-05" ixy="0.0" ixz="0.0" iyy="1.2e-05" iyz="0.0" izz="2.3e-05"/>
    </inertial>
    <visual>
      <origin rpy="0 0 0" xyz="0 0 0"/>
      <geometry>
        <mesh filename="delta-meshes/qbmove_pulley.stl" scale="0.001 0.001 0.001"/>
      </geometry>
      <material name="qbmove/shaft"/>
    </visual>
  </link>
  <joint name="delta_qbmove_2_stiffness_preset_virtual_joint" type="revolute">
    <origin rpy="0 0 0" xyz="0 0 0"/>
    <parent link="delta_qbmove_2_cube_link"/>
    <child link="delta_qbmove_2_stiffness_preset_virtual_link"/>
    <axis xyz="0 0 1"/>
    <dynamics damping="0.0" friction="0.0"/>
    <limit effort="100" lower="0.0" upper="1.0" velocity="100"/>
  </joint>
  <link name="delta_qbmove_2_stiffness_preset_virtual_link"/>
  <joint name="delta_qbmove_2_c_flange_axis_fixed_joint" type="fixed">
    <origin rpy="2.355 0 1.57" xyz="-0.0375 -0.024 -0.0375"/>
    <parent link="delta_qbmove_2_shaft_link"/>
    <child link="delta_qbmove_2_c_flange_axis_link"/>
  </joint>
  <link name="delta_qbmove_2_c_flange_axis_link">
    <inertial>
      <mass value="0.0"/>
      <origin xyz="0.0 0.0 0.0"/>
      <inertia ixx="0.0" ixy="0.0" ixz="0.0" iyy="0.0" iyz="0.0" izz="0.0"/>
    </inertial>
    <visual>
      <origin rpy="0 0 0" xyz="0 0 0"/>
      <geometry>
        <mesh filename="delta-meshes/qb_delta_c_flange.stl" scale="0.001 0.001 0.001"/>
      </geometry>
      <material name="qbmove/flange"/>
    </visual>
  </link>
  <joint name="delta_qbmove_2_upperarm_joint" type="fixed">
    <origin rpy="0 1.57 0" xyz="0 -0.035 0.02"/>
    <parent link="delta_qbmove_2_c_flange_axis_link"/>
    <child link="delta_qbmove_2_upperarm_link"/>
  </joint>
  <link name="delta_qbmove_2_upperarm_link"/>
  <joint name="delta_ee_fk_x_joint" type="prismatic">
    <origin rpy="0 0 0" xyz="0 0 0"/>
    <parent link="delta_base_frame_link"/>
    <child link="delta_ee_fk_1_link"/>
    <axis xyz="1 0 0"/>
    <dynamics damping="0.0" friction="0.0"/>
    <limit effort="100" lower="-0.25" upper="0.25" velocity="100"/>
  </joint>
  <link name="delta_ee_fk_1_link"/>
  <joint name="delta_ee_fk_y_joint" type="prismatic">
    <origin rpy="0 0 0" xyz="0 0 0"/>
    <parent link="delta_ee_fk_1_link"/>
    <child link="delta_ee_fk_2_link"/>
    <axis xyz="0 1 0"/>
    <dynamics damping="0.0" friction="0.0"/>
    <limit effort="100" lower="-0.25" upper="0.25" velocity="100"/>
  </joint>
  <link name="delta_ee_fk_2_link"/>
  <joint name="delta_ee_fk_z_joint" type="prismatic">
    <origin rpy="0 0 0" xyz="0 0 0"/>
    <parent link="delta_ee_fk_2_link"/>
    <child link="delta_ee_frame_link"/>
    <axis xyz="0 0 1"/>
    <dynamics damping="0.0" friction="0.0"/>
    <limit effort="100" lower="-0.25" upper="0.25" velocity="100"/>
  </joint>
  <link name="delta_ee_frame_link"/>
  <joint name="delta_qbmove_1_forearm_joint" type="fixed">
    <origin rpy="1.57 0 0" xyz="0.0455 0 0"/>
    <parent link="delta_ee_frame_link"/>
    <child link="delta_qbmove_1_forearm_link"/>
  </joint>
  <link name="delta_qbmove_1_forearm_link"/>
  <joint name="delta_qbmove_1_free_down_joint" type="continuous">
    <origin rpy="0 0 -1.57" xyz="0 0 -0.014"/>
    <parent link="delta_qbmove_1_forearm_link"/>
    <child link="delta_qbmove_1_free_down_link"/>
    <axis xyz="0 0 1"/>
  </joint>
  <link name="delta_qbmove_1_free_down_link">
    <visual>
      <origin rpy="0 0 0" xyz="0 0 0"/>
      <geometry>
        <mesh filename="delta-meshes/qb_delta_joint.stl" scale="0.001 0.001 0.001"/>
      </geometry>
      <material name="qbmove/default"/>
    </visual>
  </link>
  <joint name="delta_qbmove_1_free_l_joint" type="continuous">
    <origin rpy="0 1.57 0" xyz="0 0 0.0513"/>
    <parent link="delta_qbmove_1_free_down_link"/>
    <child link="delta_qbmove_1_free_l_link"/>
    <axis xyz="0 0 1"/>
  </joint>
  <link name="delta_qbmove_1_free_l_link">
  </link>
  <joint name="delta_qbmove_1_forearm_l_fixed_joint" type="fixed">
    <origin rpy="1.57 1.57 0" xyz="0 0 0"/>
    <parent link="delta_qbmove_1_free_l_link"/>
    <child link="delta_qbmove_1_forearm_l_link"/>
  </joint>
  <link name="delta_qbmove_1_forearm_l_link">
    <inertial>
      <mass value="0.0"/>
      <origin xyz="0.0 0.0 0.0"/>
      <inertia ixx="0.0" ixy="0.0" ixz="0.0" iyy="0.0" iyz="0.0" izz="0.0"/>
    </inertial>
    <visual>
      <origin rpy="0 0 0" xyz="0 0 0"/>
      <geometry>
        <mesh filename="delta-meshes/qb_delta_link.stl" scale="0.001 0.001 0.001"/>
      </geometry>
      <material name="qbmove/default"/>
    </visual>
  </link>
  <joint name="delta_qbmove_1_free_r_joint" type="continuous">
    <origin rpy="0 1.57 0" xyz="0 0 -0.0263"/>
    <parent link="delta_qbmove_1_free_down_link"/>
    <child link="delta_qbmove_1_free_r_link"/>
    <axis xyz="0 0 1"/>
    <mimic joint="delta_qbmove_1_free_l_joint" multiplier="1"/>
  </joint>
  <link name="delta_qbmove_1_free_r_link">
  </link>
  <joint name="delta_qbmove_1_forearm_r_fixed_joint" type="fixed">
    <origin rpy="1.57 1.57 0" xyz="0 0 0"/>
    <parent link="delta_qbmove_1_free_r_link"/>
    <child link="delta_qbmove_1_forearm_r_link"/>
  </joint>
  <link name="delta_qbmove_1_forearm_r_link">
    <inertial>
      <mass value="0.0"/>
      <origin xyz="0.0 0.0 0.0"/>
      <inertia ixx="0.0" ixy="0.0" ixz="0.0" iyy="0.0" iyz="0.0" izz="0.0"/>
    </inertial>
    <visual>
      <origin rpy="0 0 0" xyz="0 0 0"/>
      <geometry>
        <mesh filename="delta-meshes/qb_delta_link.stl" scale="0.001 0.001 0.001"/>
      </geometry>
      <material name="qbmove/default"/>
    </visual>
  </link>
  <joint name="delta_qbmove_1_free_up_joint" type="continuous">
    <origin rpy="0 1.57 0" xyz="0 0 -0.156"/>
    <parent link="delta_qbmove_1_forearm_l_link"/>
    <child link="delta_qbmove_1_free_up_link"/>
    <axis xyz="0 0 1"/>
    <mimic joint="delta_qbmove_1_free_l_joint" multiplier="1"/>
  </joint>
  <link name="delta_qbmove_1_free_up_link">
  </link>
  <joint name="delta_qbmove_1_forearm_up_fixed_joint" type="fixed">
    <origin rpy="0 -1.57 1.57" xyz="0 0.0513 0"/>
    <parent link="delta_qbmove_1_free_up_link"/>
    <child link="delta_qbmove_1_forearm_up_link"/>
  </joint>
  <link name="delta_qbmove_1_forearm_up_link">
    <inertial>
      <mass value="0.0"/>
      <origin xyz="0.0 0.0 0.0"/>
      <inertia ixx="0.0" ixy="0.0" ixz="0.0" iyy="0.0" iyz="0.0" izz="0.0"/>
    </inertial>
    <visual>
      <origin rpy="0 0 0" xyz="0 0 0"/>
      <geometry>
        <mesh filename="delta-meshes/qb_delta_joint.stl" scale="0.001 0.001 0.001"/>
      </geometry>
      <material name="qbmove/default"/>
    </visual>
  </link>
  <joint name="delta_qbmove_3_forearm_joint" type="fixed">
    <origin rpy="1.57 0 -2.095" xyz="-0.0227 -0.0394 0"/>
    <parent link="delta_ee_frame_link"/>
    <child link="delta_qbmove_3_forearm_link"/>
  </joint>
  <link name="delta_qbmove_3_forearm_link"/>
  <joint name="delta_qbmove_3_free_down_joint" type="continuous">
    <origin rpy="0 0 -1.57" xyz="0 0 -0.014"/>
    <parent link="delta_qbmove_3_forearm_link"/>
    <child link="delta_qbmove_3_free_down_link"/>
    <axis xyz="0 0 1"/>
  </joint>
  <link name="delta_qbmove_3_free_down_link">
    <visual>
      <origin rpy="0 0 0" xyz="0 0 0"/>
      <geometry>
        <mesh filename="delta-meshes/qb_delta_joint.stl" scale="0.001 0.001 0.001"/>
      </geometry>
      <material name="qbmove/default"/>
    </visual>
  </link>
  <joint name="delta_qbmove_3_free_l_joint" type="continuous">
    <origin rpy="0 1.57 0" xyz="0 0 0.0513"/>
    <parent link="delta_qbmove_3_free_down_link"/>
    <child link="delta_qbmove_3_free_l_link"/>
    <axis xyz="0 0 1"/>
  </joint>
  <link name="delta_qbmove_3_free_l_link">
  </link>
  <joint name="delta_qbmove_3_forearm_l_fixed_joint" type="fixed">
    <origin rpy="1.57 1.57 0" xyz="0 0 0"/>
    <parent link="delta_qbmove_3_free_l_link"/>
    <child link="delta_qbmove_3_forearm_l_link"/>
  </joint>
  <link name="delta_qbmove_3_forearm_l_link">
    <inertial>
      <mass value="0.0"/>
      <origin xyz="0.0 0.0 0.0"/>
      <inertia ixx="0.0" ixy="0.0" ixz="0.0" iyy="0.0" iyz="0.0" izz="0.0"/>
    </inertial>
    <visual>
      <origin rpy="0 0 0" xyz="0 0 0"/>
      <geometry>
        <mesh filename="delta-meshes/qb_delta_link.stl" scale="0.001 0.001 0.001"/>
      </geometry>
      <material name="qbmove/default"/>
    </visual>
  </link>
  <joint name="delta_qbmove_3_free_r_joint" type="continuous">
    <origin rpy="0 1.57 0" xyz="0 0 -0.0263"/>
    <parent link="delta_qbmove_3_free_down_link"/>
    <child link="delta_qbmove_3_free_r_link"/>
    <axis xyz="0 0 1"/>
    <mimic joint="delta_qbmove_3_free_l_joint" multiplier="1"/>
  </joint>
  <link name="delta_qbmove_3_free_r_link">
  </link>
  <joint name="delta_qbmove_3_forearm_r_fixed_joint" type="fixed">
    <origin rpy="1.57 1.57 0" xyz="0 0 0"/>
    <parent link="delta_qbmove_3_free_r_link"/>
    <child link="delta_qbmove_3_forearm_r_link"/>
  </joint>
  <link name="delta_qbmove_3_forearm_r_link">
    <inertial>
      <mass value="0.0"/>
      <origin xyz="0.0 0.0 0.0"/>
      <inertia ixx="0.0" ixy="0.0" ixz="0.0" iyy="0.0" iyz="0.0" izz="0.0"/>
    </inertial>
    <visual>
      <origin rpy="0 0 0" xyz="0 0 0"/>
      <geometry>
        <mesh filename="delta-meshes/qb_delta_link.stl" scale="0.001 0.001 0.001"/>
      </geometry>
      <material name="qbmove/default"/>
    </visual>
  </link>
  <joint name="delta_qbmove_3_free_up_joint" type="continuous">
    <origin rpy="0 1.57 0" xyz="0 0 -0.156"/>
    <parent link="delta_qbmove_3_forearm_l_link"/>
    <child link="delta_qbmove_3_free_up_link"/>
    <axis xyz="0 0 1"/>
    <mimic joint="delta_qbmove_3_free_l_joint" multiplier="1"/>
  </joint>
  <link name="delta_qbmove_3_free_up_link">
  </link>
  <joint name="delta_qbmove_3_forearm_up_fixed_joint" type="fixed">
    <origin rpy="0 -1.57 1.57" xyz="0 0.0513 0"/>
    <parent link="delta_qbmove_3_free_up_link"/>
    <child link="delta_qbmove_3_forearm_up_link"/>
  </joint>
  <link name="delta_qbmove_3_forearm_up_link">
    <inertial>
      <mass value="0.0"/>
      <origin xyz="0.0 0.0 0.0"/>
      <inertia ixx="0.0" ixy="0.0" ixz="0.0" iyy="0.0" iyz="0.0" izz="0.0"/>
    </inertial>
    <visual>
      <origin rpy="0 0 0" xyz="0 0 0"/>
      <geometry>
        <mesh filename="delta-meshes/qb_delta_joint.stl" scale="0.001 0.001 0.001"/>
      </geometry>
      <material name="qbmove/default"/>
    </visual>
  </link>
  <joint name="delta_qbmove_2_forearm_joint" type="fixed">
    <origin rpy="1.57 0 2.095" xyz="-0.0227 0.0394 0"/>
    <parent link="delta_ee_frame_link"/>
    <child link="delta_qbmove_2_forearm_link"/>
  </joint>
  <link name="delta_qbmove_2_forearm_link"/>
  <joint name="delta_qbmove_2_free_down_joint" type="continuous">
    <origin rpy="0 0 -1.57" xyz="0 0 -0.014"/>
    <parent link="delta_qbmove_2_forearm_link"/>
    <child link="delta_qbmove_2_free_down_link"/>
    <axis xyz="0 0 1"/>
  </joint>
  <link name="delta_qbmove_2_free_down_link">
    <visual>
      <origin rpy="0 0 0" xyz="0 0 0"/>
      <geometry>
        <mesh filename="delta-meshes/qb_delta_joint.stl" scale="0.001 0.001 0.001"/>
      </geometry>
      <material name="qbmove/default"/>
    </visual>
  </link>
  <joint name="delta_qbmove_2_free_l_joint" type="continuous">
    <origin rpy="0 1.57 0" xyz="0 0 0.0513"/>
    <parent link="delta_qbmove_2_free_down_link"/>
    <child link="delta_qbmove_2_free_l_link"/>
    <axis xyz="0 0 1"/>
  </joint>
  <link name="delta_qbmove_2_free_l_link">
  </link>
  <joint name="delta_qbmove_2_forearm_l_fixed_joint" type="fixed">
    <origin rpy="1.57 1.57 0" xyz="0 0 0"/>
    <parent link="delta_qbmove_2_free_l_link"/>
    <child link="delta_qbmove_2_forearm_l_link"/>
  </joint>
  <link name="delta_qbmove_2_forearm_l_link">
    <inertial>
      <mass value="0.0"/>
      <origin xyz="0.0 0.0 0.0"/>
      <inertia ixx="0.0" ixy="0.0" ixz="0.0" iyy="0.0" iyz="0.0" izz="0.0"/>
    </inertial>
    <visual>
      <origin rpy="0 0 0" xyz="0 0 0"/>
      <geometry>
        <mesh filename="delta-meshes/qb_delta_link.stl" scale="0.001 0.001 0.001"/>
      </geometry>
      <material name="qbmove/default"/>
    </visual>
  </link>
  <joint name="delta_qbmove_2_free_r_joint" type="continuous">
    <origin rpy="0 1.57 0" xyz="0 0 -0.0263"/>
    <parent link="delta_qbmove_2_free_down_link"/>
    <child link="delta_qbmove_2_free_r_link"/>
    <axis xyz="0 0 1"/>
    <mimic joint="delta_qbmove_2_free_l_joint" multiplier="1"/>
  </joint>
  <link name="delta_qbmove_2_free_r_link">
  </link>
  <joint name="delta_qbmove_2_forearm_r_fixed_joint" type="fixed">
    <origin rpy="1.57 1.57 0" xyz="0 0 0"/>
    <parent link="delta_qbmove_2_free_r_link"/>
    <child link="delta_qbmove_2_forearm_r_link"/>
  </joint>
  <link name="delta_qbmove_2_forearm_r_link">
    <inertial>
      <mass value="0.0"/>
      <origin xyz="0.0 0.0 0.0"/>
      <inertia ixx="0.0" ixy="0.0" ixz="0.0" iyy="0.0" iyz="0.0" izz="0.0"/>
    </inertial>
    <visual>
      <origin rpy="0 0 0" xyz="0 0 0"/>
      <geometry>
        <mesh filename="delta-meshes/qb_delta_link.stl" scale="0.001 0.001 0.001"/>
      </geometry>
      <material name="qbmove/default"/>
    </visual>
  </link>
  <joint name="delta_qbmove_2_free_up_joint" type="continuous">
    <origin rpy="0 1.57 0" xyz="0 0 -0.156"/>
    <parent link="delta_qbmove_2_forearm_l_link"/>
    <child link="delta_qbmove_2_free_up_link"/>
    <axis xyz="0 0 1"/>
    <mimic joint="delta_qbmove_2_free_l_joint" multiplier="1"/>
  </joint>
  <link name="delta_qbmove_2_free_up_link">
  </link>
  <joint name="delta_qbmove_2_forearm_up_fixed_joint" type="fixed">
    <origin rpy="0 -1.57 1.57" xyz="0 0.0513 0"/>
    <parent link="delta_qbmove_2_free_up_link"/>
    <child link="delta_qbmove_2_forearm_up_link"/>
  </joint>
  <link name="delta_qbmove_2_forearm_up_link">
    <inertial>
      <mass value="0.0"/>
      <origin xyz="0.0 0.0 0.0"/>
      <inertia ixx="0.0" ixy="0.0" ixz="0.0" iyy="0.0" iyz="0.0" izz="0.0"/>
    </inertial>
    <visual>
      <origin rpy="0 0 0" xyz="0 0 0"/>
      <geometry>
        <mesh filename="delta-meshes/qb_delta_joint.stl" scale="0.001 0.001 0.001"/>
      </geometry>
      <material name="qbmove/default"/>
    </visual>
  </link>
  <joint name="delta_gripper_plate_fixed_joint" type="fixed">
    <origin rpy="1.57 0 -0.52" xyz="0 0 0.0198"/>
    <parent link="delta_ee_frame_link"/>
    <child link="delta_gripper_plate_link"/>
  </joint>
  <link name="delta_gripper_plate_link">
    <inertial>
      <mass value="0.0"/>
      <origin xyz="0.0 0.0 0.0"/>
      <inertia ixx="0.0" ixy="0.0" ixz="0.0" iyy="0.0" iyz="0.0" izz="0.0"/>
    </inertial>
    <visual>
      <origin rpy="0 0 0" xyz="0 0 0"/>
      <geometry>
        <mesh filename="delta-meshes/qb_delta_gripper_plate.stl" scale="0.001 0.001 0.001"/>
      </geometry>
      <material name="qbmove/flange"/>
    </visual>
  </link>
  <joint name="delta_qbmove_4_flat_flange_fixed_joint" type="fixed">
    <origin rpy="-1.57 -2.62 0" xyz="0 0.007 0"/>
    <parent link="delta_gripper_plate_link"/>
    <child link="delta_qbmove_4_flat_flange_link"/>
  </joint>
  <link name="delta_qbmove_4_flat_flange_link">
    <inertial>
      <mass value="0.0"/>
      <origin xyz="0.0 0.0 0.0"/>
      <inertia ixx="0.0" ixy="0.0" ixz="0.0" iyy="0.0" iyz="0.0" izz="0.0"/>
    </inertial>
    <visual>
      <origin rpy="0 0 0" xyz="0 0 0"/>
      <geometry>
        <mesh filename="delta-meshes/qb_flat_flange.stl" scale="0.001 0.001 0.001"/>
      </geometry>
      <material name="qbmove/flange"/>
    </visual>
  </link>
  <joint name="delta_qbmove_4_cube_fixed_joint" type="fixed">
    <origin rpy="0 -1.57 0" xyz="0.033 0 0.033"/>
    <parent link="delta_qbmove_4_flat_flange_link"/>
    <child link="delta_qbmove_4_cube_link"/>
  </joint>
  <link name="delta_qbmove_4_cube_link">
    <inertial>
      <mass value="0.6"/>
      <origin xyz="0.0 0.0 0.05"/>
      <inertia ixx="0.001" ixy="0.0" ixz="0.0" iyy="0.001" iyz="0.0" izz="0.001"/>
    </inertial>
    <visual>
      <origin rpy="0 0 0" xyz="0 0 0"/>
      <geometry>
        <mesh filename="delta-meshes/qbmove_frame.stl" scale="0.001 0.001 0.001"/>
      </geometry>
      <material name="qbmove/cube"/>
    </visual>
  </link>
  <joint name="delta_qbmove_4_motor_1_joint" type="revolute">
    <origin rpy="0 0 0" xyz="0.02 0.02 0.02"/>
    <parent link="delta_qbmove_4_cube_link"/>
    <child link="delta_qbmove_4_motor_1_link"/>
    <axis xyz="0 1 0"/>
    <dynamics damping="0.0" friction="0.0"/>
    <limit effort="100" lower="-2.876" upper="2.876" velocity="100"/>
  </joint>
  <link name="delta_qbmove_4_motor_1_link">
    <inertial>
      <mass value="0.05"/>
      <origin xyz="0.0 0.0 0.025"/>
      <inertia ixx="1.2e-05" ixy="0.0" ixz="0.0" iyy="1.2e-05" iyz="0.0" izz="3e-06"/>
    </inertial>
  </link>
  <joint name="delta_qbmove_4_motor_2_joint" type="revolute">
    <origin rpy="0 0 0" xyz="-0.02 -0.02 0.02"/>
    <parent link="delta_qbmove_4_cube_link"/>
    <child link="delta_qbmove_4_motor_2_link"/>
    <axis xyz="0 1 0"/>
    <dynamics damping="0.0" friction="0.0"/>
    <limit effort="100" lower="-2.876" upper="2.876" velocity="100"/>
  </joint>
  <link name="delta_qbmove_4_motor_2_link">
    <inertial>
      <mass value="0.05"/>
      <origin xyz="0.0 0.0 0.025"/>
      <inertia ixx="1.2e-05" ixy="0.0" ixz="0.0" iyy="1.2e-05" iyz="0.0" izz="3e-06"/>
    </inertial>
  </link>
  <joint name="delta_qbmove_4_shaft_joint" type="revolute">
    <origin rpy="1.57 0 0" xyz="0 0 0.056"/>
    <parent link="delta_qbmove_4_cube_link"/>
    <child link="delta_qbmove_4_shaft_link"/>
    <axis xyz="0 1 0"/>
    <dynamics damping="0.0" friction="0.0"/>
    <limit effort="100" lower="-2.876" upper="2.876" velocity="100"/>
  </joint>
  <link name="delta_qbmove_4_shaft_link">
    <inertial>
      <mass value="0.05"/>
      <origin xyz="0.0 0.0 0.005"/>
      <inertia ixx="1.2e-05" ixy="0.0" ixz="0.0" iyy="1.2e-05" iyz="0.0" izz="2.3e-05"/>
    </inertial>
    <visual>
      <origin rpy="0 0 0" xyz="0 0 0"/>
      <geometry>
        <mesh filename="delta-meshes/qbmove_pulley.stl" scale="0.001 0.001 0.001"/>
      </geometry>
      <material name="qbmove/shaft"/>
    </visual>
  </link>
  <joint name="delta_qbmove_4_stiffness_preset_virtual_joint" type="revolute">
    <origin rpy="0 0 0" xyz="0 0 0"/>
    <parent link="delta_qbmove_4_cube_link"/>
    <child link="delta_qbmove_4_stiffness_preset_virtual_link"/>
    <axis xyz="0 0 1"/>
    <dynamics damping="0.0" friction="0.0"/>
    <limit effort="100" lower="0.0" upper="1.0" velocity="100"/>
  </joint>
  <link name="delta_qbmove_4_stiffness_preset_virtual_link"/>
  <joint name="delta_qbmove_4_finger_up_fixed_joint" type="fixed">
    <origin rpy="-1.57 0 0" xyz="0 0.0165 0"/>
    <parent link="delta_qbmove_4_shaft_link"/>
    <child link="delta_qbmove_4_finger_up_link"/>
  </joint>
  <link name="delta_qbmove_4_finger_up_link">
    <inertial>
      <mass value="0.0"/>
      <origin xyz="0.0 0.0 0.0"/>
      <inertia ixx="0.0" ixy="0.0" ixz="0.0" iyy="0.0" iyz="0.0" izz="0.0"/>
    </inertial>
    <visual>
      <origin rpy="0 0 0" xyz="0 0 0"/>
      <geometry>
        <mesh filename="delta-meshes/qbmove_finger_up.stl" scale="0.001 0.001 0.001"/>
      </geometry>
      <material name="qbmove/flange"/>
    </visual>
  </link>
  <joint name="delta_qbmove_4_finger_down_fixed_joint" type="fixed">
    <origin rpy="0 1.57 1.57" xyz="0 -0.033 0.033"/>
    <parent link="delta_qbmove_4_cube_link"/>
    <child link="delta_qbmove_4_finger_down_link"/>
  </joint>
  <link name="delta_qbmove_4_finger_down_link">
    <inertial>
      <mass value="0.0"/>
      <origin xyz="0.0 0.0 0.0"/>
      <inertia ixx="0.0" ixy="0.0" ixz="0.0" iyy="0.0" iyz="0.0" izz="0.0"/>
    </inertial>
    <visual>
      <origin rpy="0 0 0" xyz="0 0 0"/>
      <geometry>
        <mesh filename="delta-meshes/qbmove_finger_down.stl" scale="0.001 0.001 0.001"/>
      </geometry>
      <material name="qbmove/flange"/>
    </visual>
  </link>
</robot>